#VRML_SIM R2020b utf8
WorldInfo {
  coordinateSystem "NUE"
}
Viewpoint {
  orientation 0.9993251013187591 0.030818420856925155 0.019989167319759783 5.131772444998734
  position -0.924412530262486 16.72624291104881 8.264936711135606
}
TexturedBackground {
}
TexturedBackgroundLight {
}
RectangleArena {
  floorSize 20 20
  wallThickness 0.1
  wallHeight 0.5
}
DEF robot0 Robot {
  translation -2.73191 0.0397206 1.89998
  rotation 0 1 0 2.61799
  children [
    Emitter {
      channel -1
    }
    Receiver {
      channel -1
    }
    DEF Body Shape {
      appearance PBRAppearance {
        baseColor 0 1 0
        metalness 0
      }
      geometry Box {
        size 0.1 0.05 0.2
      }
    }
    HingeJoint {
      jointParameters HingeJointParameters {
        position 43884.96607707316
        anchor 0.06 0 0.05
      }
      device [
        RotationalMotor {
          name "wheel1"
        }
      ]
      endPoint Solid {
        translation 0.060000000000000026 -3.780056778713794e-18 0.04999999999999998
        rotation 0.7072380854001235 -0.7066751168860492 -0.02060508999389237 3.1828298187646387
        children [
          DEF Wheel Shape {
            appearance PBRAppearance {
              baseColor 1 0 0
              metalness 0
            }
            geometry Cylinder {
              height 0.02
              radius 0.04
            }
          }
        ]
        boundingObject USE Wheel
        physics DEF Physics_wh Physics {
        }
      }
    }
    HingeJoint {
      jointParameters HingeJointParameters {
        position 40411.70945349283
        anchor -0.06 0 0.05
      }
      device [
        RotationalMotor {
          name "wheel2"
        }
      ]
      endPoint Solid {
        translation -0.06 1.0560456843632646e-17 0.050000000000000024
        rotation -0.6073142906920832 0.6068308625073404 0.5127627683732207 2.193334637453841
        children [
          USE Wheel
        ]
        name "solid(1)"
        boundingObject USE Wheel
        physics USE Physics_wh
      }
    }
    HingeJoint {
      jointParameters HingeJointParameters {
        position 43884.966362714615
        anchor 0.06 0 -0.05
      }
      device [
        RotationalMotor {
          name "wheel3"
        }
      ]
      endPoint Solid {
        translation 0.060000000000000026 3.778984224312497e-18 -0.04999999999999998
        rotation 0.7072366097480942 -0.7066736424086548 -0.02070606087372919 3.183031835071632
        children [
          USE Wheel
        ]
        name "solid(2)"
        boundingObject USE Wheel
        physics USE Physics_wh
      }
    }
    HingeJoint {
      jointParameters HingeJointParameters {
        position 40411.709798414995
        anchor -0.06 0 -0.05
      }
      device [
        RotationalMotor {
          name "wheel4"
        }
      ]
      endPoint Solid {
        translation -0.06 2.107030821802262e-09 -0.0499999875234838
        rotation -0.6072584616914315 0.6067750779471254 0.5128948873662286 2.193125324605423
        children [
          USE Wheel
        ]
        name "solid(3)"
        boundingObject USE Wheel
        physics USE Physics_wh
      }
    }
    DistanceSensor {
      translation 0.02 0 0.1
      rotation 0 1 0 -1.27
      children [
        DEF sensor Shape {
          appearance PBRAppearance {
            baseColor 0 1 1
            metalness 0
          }
          geometry Box {
            size 0.01 0.01 0.01
          }
        }
      ]
      name "ds_left"
      boundingObject USE sensor
      physics Physics {
      }
    }
    DistanceSensor {
      translation -0.02 0 0.1
      rotation 0 1 0 -1.87
      children [
        DEF sensor Shape {
          appearance PBRAppearance {
            baseColor 0 1 1
            metalness 0
          }
          geometry Box {
            size 0.01 0.01 0.01
          }
        }
      ]
      name "ds_right"
      boundingObject USE sensor
      physics Physics {
      }
    }
    GPS {
      translation 0 0.03 0
      children [
        Solid {
          children [
            Shape {
              appearance PBRAppearance {
              }
              geometry Cylinder {
                height 0.02
                radius 0.01
              }
            }
          ]
        }
      ]
      name "global"
    }
    InertialUnit {
      translation 0 0.03 0.04
      children [
        Shape {
          appearance PBRAppearance {
            baseColor 0 0 0.7
            metalness 0
          }
          geometry Box {
            size 0.02 0.02 0.02
          }
        }
      ]
      name "imu"
    }
  ]
  name "robot0_name"
  boundingObject USE Body
  physics Physics {
  }
  controller "robot_controller_v2"
  controllerArgs [
    "0"
  ]
  supervisor TRUE
}
DEF robot1 Robot {
  translation -2.7341704704117946 0.03972062055835439 0.5168090985672764
  rotation 2.08722e-08 1 -2.6853e-07 -1.3079996938995748
  children [
    Emitter {
      channel -1
    }
    Receiver {
      channel -1
    }
    DEF Body Shape {
      appearance PBRAppearance {
        baseColor 0 1 0
        metalness 0
      }
      geometry Box {
        size 0.1 0.05 0.2
      }
    }
    HingeJoint {
      jointParameters HingeJointParameters {
        position 43858.02215799354
        anchor 0.06 0 0.05
      }
      device [
        RotationalMotor {
          name "wheel1"
        }
      ]
      endPoint Solid {
        translation 0.060000000000000026 -2.244419343582714e-17 0.049999999999999996
        rotation 0.5392933390244743 -0.5388640561903215 0.647138488601897 1.9921441284262613
        children [
          DEF Wheel Shape {
            appearance PBRAppearance {
              baseColor 1 0 0
              metalness 0
            }
            geometry Cylinder {
              height 0.02
              radius 0.04
            }
          }
        ]
        boundingObject USE Wheel
        physics DEF Physics_wh Physics {
        }
      }
    }
    HingeJoint {
      jointParameters HingeJointParameters {
        position 40412.73337410005
        anchor -0.06 0 0.05
      }
      device [
        RotationalMotor {
          name "wheel2"
        }
      ]
      endPoint Solid {
        translation -0.06 -1.3406527724478341e-17 0.050000000000000024
        rotation -0.33034028161932044 0.33007732748644486 0.8842648111392167 1.692695681702468
        children [
          USE Wheel
        ]
        name "solid(1)"
        boundingObject USE Wheel
        physics USE Physics_wh
      }
    }
    HingeJoint {
      jointParameters HingeJointParameters {
        position 43858.02244161523
        anchor 0.06 0 -0.05
      }
      device [
        RotationalMotor {
          name "wheel3"
        }
      ]
      endPoint Solid {
        translation 0.060000000000000026 2.2441054373731387e-17 -0.049999999999999996
        rotation 0.5393584629371352 -0.5389291282637043 0.6470300172070959 1.9922970929491646
        children [
          USE Wheel
        ]
        name "solid(2)"
        boundingObject USE Wheel
        physics USE Physics_wh
      }
    }
    HingeJoint {
      jointParameters HingeJointParameters {
        position 40412.733717444135
        anchor -0.06 0 -0.05
      }
      device [
        RotationalMotor {
          name "wheel4"
        }
      ]
      endPoint Solid {
        translation -0.06 -9.561144808813505e-09 -0.049999991712205025
        rotation -0.33020502110644734 0.3299421746422811 0.8843657645049435 1.6925823681196934
        children [
          USE Wheel
        ]
        name "solid(3)"
        boundingObject USE Wheel
        physics USE Physics_wh
      }
    }
    DistanceSensor {
      translation 0.02 0 0.1
      rotation 0 1 0 -1.27
      children [
        DEF sensor Shape {
          appearance PBRAppearance {
            baseColor 0 1 1
            metalness 0
          }
          geometry Box {
            size 0.01 0.01 0.01
          }
        }
      ]
      name "ds_left"
      boundingObject USE sensor
      physics Physics {
      }
    }
    DistanceSensor {
      translation -0.02 0 0.1
      rotation 0 1 0 -1.87
      children [
        DEF sensor Shape {
          appearance PBRAppearance {
            baseColor 0 1 1
            metalness 0
          }
          geometry Box {
            size 0.01 0.01 0.01
          }
        }
      ]
      name "ds_right"
      boundingObject USE sensor
      physics Physics {
      }
    }
    GPS {
      translation 0 0.03 0
      children [
        Solid {
          children [
            Shape {
              appearance PBRAppearance {
              }
              geometry Cylinder {
                height 0.02
                radius 0.01
              }
            }
          ]
        }
      ]
      name "global"
    }
    InertialUnit {
      translation 0 0.03 0.04
      children [
        Shape {
          appearance PBRAppearance {
            baseColor 0 0 0.7
            metalness 0
          }
          geometry Box {
            size 0.02 0.02 0.02
          }
        }
      ]
      name "imu"
    }
  ]
  name "robot1_name"
  boundingObject USE Body
  physics Physics {
  }
  controller "robot_controller_v2"
  controllerArgs [
    "1"
  ]
  supervisor TRUE
}
DEF robot2 Robot {
  translation -2.64938 0.0397283 -1.44746
  rotation -2.07040999954099e-05 0.9999999997782998 -3.839349999148815e-06 -2.3561953071795863
  children [
    Emitter {
      channel -1
    }
    Receiver {
      channel -1
    }
    DEF Body Shape {
      appearance PBRAppearance {
        baseColor 0 1 0
        metalness 0
      }
      geometry Box {
        size 0.1 0.05 0.2
      }
    }
    HingeJoint {
      jointParameters HingeJointParameters {
        position 43885.92607557584
        anchor 0.06 0 0.05
      }
      device [
        RotationalMotor {
          name "wheel1"
        }
      ]
      endPoint Solid {
        translation 0.060000000000000026 1.58989044287447e-17 0.04999999999999999
        rotation 0.6580162906112149 -0.65749250313284 -0.3670397384676071 3.845655200995858
        children [
          DEF Wheel Shape {
            appearance PBRAppearance {
              baseColor 1 0 0
              metalness 0
            }
            geometry Cylinder {
              height 0.02
              radius 0.04
            }
          }
        ]
        boundingObject USE Wheel
        physics DEF Physics_wh Physics {
        }
      }
    }
    HingeJoint {
      jointParameters HingeJointParameters {
        position 40412.02945664714
        anchor -0.06 0 0.05
      }
      device [
        RotationalMotor {
          name "wheel2"
        }
      ]
      endPoint Solid {
        translation -0.06 7.020215543850554e-18 0.05
        rotation -0.5460247821449858 0.5455901410155024 0.6357580792331349 2.008275274218866
        children [
          USE Wheel
        ]
        name "solid(1)"
        boundingObject USE Wheel
        physics USE Physics_wh
      }
    }
    HingeJoint {
      jointParameters HingeJointParameters {
        position 43885.92635935684
        anchor 0.06 0 -0.05
      }
      device [
        RotationalMotor {
          name "wheel3"
        }
      ]
      endPoint Solid {
        translation 0.060000000000000026 -1.590006171890773e-17 -0.04999999999999999
        rotation 0.6579867320020357 -0.6574629680526074 -0.3671456198141787 3.8458419293246364
        children [
          USE Wheel
        ]
        name "solid(2)"
        boundingObject USE Wheel
        physics USE Physics_wh
      }
    }
    HingeJoint {
      jointParameters HingeJointParameters {
        position 40412.02979974228
        anchor -0.06 0 -0.05
      }
      device [
        RotationalMotor {
          name "wheel4"
        }
      ]
      endPoint Solid {
        translation -0.06 -1.9246431069749137e-09 -0.04999998749405004
        rotation -0.5459482187494368 0.5455136385651742 0.6358894656964382 2.0080880870726157
        children [
          USE Wheel
        ]
        name "solid(3)"
        boundingObject USE Wheel
        physics USE Physics_wh
      }
    }
    DistanceSensor {
      translation 0.02 0 0.1
      rotation 0 1 0 -1.27
      children [
        DEF sensor Shape {
          appearance PBRAppearance {
            baseColor 0 1 1
            metalness 0
          }
          geometry Box {
            size 0.01 0.01 0.01
          }
        }
      ]
      name "ds_left"
      boundingObject USE sensor
      physics Physics {
      }
    }
    DistanceSensor {
      translation -0.02 0 0.1
      rotation 0 1 0 -1.87
      children [
        DEF sensor Shape {
          appearance PBRAppearance {
            baseColor 0 1 1
            metalness 0
          }
          geometry Box {
            size 0.01 0.01 0.01
          }
        }
      ]
      name "ds_right"
      boundingObject USE sensor
      physics Physics {
      }
    }
    GPS {
      translation 0 0.03 0
      children [
        Solid {
          children [
            Shape {
              appearance PBRAppearance {
              }
              geometry Cylinder {
                height 0.02
                radius 0.01
              }
            }
          ]
        }
      ]
      name "global"
    }
    InertialUnit {
      translation 0 0.03 0.04
      children [
        Shape {
          appearance PBRAppearance {
            baseColor 0 0 0.7
            metalness 0
          }
          geometry Box {
            size 0.02 0.02 0.02
          }
        }
      ]
      name "imu"
    }
  ]
  name "robot2_name"
  boundingObject USE Body
  physics Physics {
  }
  controller "robot_controller_v2"
  controllerArgs [
    "2"
  ]
  supervisor TRUE
}
DEF robot3 Robot {
  translation -2.7162 0.0397178 -0.456901
  rotation 6.904089999752373e-06 0.9999999999641334 4.905819999824045e-06 -1.9645796938995748
  children [
    Emitter {
      channel -1
    }
    Receiver {
      channel -1
    }
    DEF Body Shape {
      appearance PBRAppearance {
        baseColor 0 1 0
        metalness 0
      }
      geometry Box {
        size 0.1 0.05 0.2
      }
    }
    HingeJoint {
      jointParameters HingeJointParameters {
        position 43886.50208791606
        anchor 0.06 0 0.05
      }
      device [
        RotationalMotor {
          name "wheel1"
        }
      ]
      endPoint Solid {
        translation 0.060000000000000026 2.065924928935765e-17 0.05000000000000001
        rotation 0.5730780754064138 -0.5726218995878044 -0.5862471147911392 4.202779069205771
        children [
          DEF Wheel Shape {
            appearance PBRAppearance {
              baseColor 1 0 0
              metalness 0
            }
            geometry Cylinder {
              height 0.02
              radius 0.04
            }
          }
        ]
        boundingObject USE Wheel
        physics DEF Physics_wh Physics {
        }
      }
    }
    HingeJoint {
      jointParameters HingeJointParameters {
        position 40417.85344378605
        anchor -0.06 0 0.05
      }
      device [
        RotationalMotor {
          name "wheel2"
        }
      ]
      endPoint Solid {
        translation -0.06 1.387459243585249e-17 0.050000000000000024
        rotation 0.6282482371842046 -0.6277481453709124 -0.45960463276420443 4.003821890932696
        children [
          USE Wheel
        ]
        name "solid(1)"
        boundingObject USE Wheel
        physics USE Physics_wh
      }
    }
    HingeJoint {
      jointParameters HingeJointParameters {
        position 43886.502372223506
        anchor 0.06 0 -0.05
      }
      device [
        RotationalMotor {
          name "wheel3"
        }
      ]
      endPoint Solid {
        translation 0.060000000000000026 -2.0657415473775043e-17 -0.05000000000000001
        rotation 0.5730220551847743 -0.5725659239588158 -0.5863565357297597 4.202941991607293
        children [
          USE Wheel
        ]
        name "solid(2)"
        boundingObject USE Wheel
        physics USE Physics_wh
      }
    }
    HingeJoint {
      jointParameters HingeJointParameters {
        position 40417.85378732571
        anchor -0.06 0 -0.05
      }
      device [
        RotationalMotor {
          name "wheel4"
        }
      ]
      endPoint Solid {
        translation -0.06 3.817734519122956e-09 -0.04999998793650389
        rotation 0.6282004387183711 -0.6277003849531313 -0.4597351797760717 4.004037551926353
        children [
          USE Wheel
        ]
        name "solid(3)"
        boundingObject USE Wheel
        physics USE Physics_wh
      }
    }
    DistanceSensor {
      translation 0.02 0 0.1
      rotation 0 1 0 -1.27
      children [
        DEF sensor Shape {
          appearance PBRAppearance {
            baseColor 0 1 1
            metalness 0
          }
          geometry Box {
            size 0.01 0.01 0.01
          }
        }
      ]
      name "ds_left"
      boundingObject USE sensor
      physics Physics {
      }
    }
    DistanceSensor {
      translation -0.02 0 0.1
      rotation 0 1 0 -1.87
      children [
        DEF sensor Shape {
          appearance PBRAppearance {
            baseColor 0 1 1
            metalness 0
          }
          geometry Box {
            size 0.01 0.01 0.01
          }
        }
      ]
      name "ds_right"
      boundingObject USE sensor
      physics Physics {
      }
    }
    GPS {
      translation 0 0.03 0
      children [
        Solid {
          children [
            Shape {
              appearance PBRAppearance {
              }
              geometry Cylinder {
                height 0.02
                radius 0.01
              }
            }
          ]
        }
      ]
      name "global"
    }
    InertialUnit {
      translation 0 0.03 0.04
      children [
        Shape {
          appearance PBRAppearance {
            baseColor 0 0 0.7
            metalness 0
          }
          geometry Box {
            size 0.02 0.02 0.02
          }
        }
      ]
      name "imu"
    }
  ]
  name "robot3_name"
  boundingObject USE Body
  physics Physics {
  }
  controller "robot_controller_v2"
  controllerArgs [
    "3"
  ]
  supervisor TRUE
}
DEF mine0 Robot {
  children [
    Shape {
      appearance PBRAppearance {
        baseColor 1 0 0
      }
      geometry Cylinder {
        height 0.5
        radius 0.05
      }
    }
  ]
  name "mine0_name"
}
DEF mine1 Robot {
  translation 1.61 0 0.91
  children [
    Shape {
      appearance PBRAppearance {
        baseColor 1 0 0
      }
      geometry Cylinder {
        height 0.5
        radius 0.05
      }
    }
  ]
  name "mine1_name"
}
DEF mine2 Robot {
  translation 2.43 0 -1.3
  children [
    Shape {
      appearance PBRAppearance {
        baseColor 1 0 0
      }
      geometry Cylinder {
        height 0.5
        radius 0.05
      }
    }
  ]
  name "mine2_name"
}
DEF mine3 Robot {
  translation 0 0 -1
  children [
    Shape {
      appearance PBRAppearance {
        baseColor 1 0 0
      }
      geometry Cylinder {
        height 0.5
        radius 0.05
      }
    }
  ]
  name "mine3_name"
}
DEF mine4 Robot {
  translation 0 0 -2
  children [
    Shape {
      appearance PBRAppearance {
        baseColor 1 0 0
      }
      geometry Cylinder {
        height 0.5
        radius 0.05
      }
    }
  ]
  name "mine4_name"
}
DEF mine5 Robot {
  translation -2.74398 0 1.91168
  children [
    Shape {
      appearance PBRAppearance {
        baseColor 1 0 0
      }
      geometry Cylinder {
        height 0.5
        radius 0.05
      }
    }
  ]
  name "mine5_name"
}
