#VRML_SIM R2020b utf8
WorldInfo {
  coordinateSystem "NUE"
}
Viewpoint {
  orientation 0.4550411407728675 -0.7186487584817194 -0.5258151026138473 4.38867946281467
  position 3.30149662974513 7.528181824676284 0.5314767017854622
}
TexturedBackground {
}
TexturedBackgroundLight {
}
RectangleArena {
  floorSize 5 6
  wallThickness 0.1
  wallHeight 0.5
}
DEF robot0 Robot {
  translation 1.6 0.0413976 1.63777
  rotation 0.9999589468592978 0.0014500888088492332 -0.008944374684167904 -0.0005175336905305317
  children [
    Receiver {
    }
    DEF Body Shape {
      appearance PBRAppearance {
        baseColor 0 1 0
        metalness 0
      }
      geometry Box {
        size 0.1 0.05 0.2
      }
    }
    HingeJoint {
      jointParameters HingeJointParameters {
        position 43816.96618303253
        anchor 0.06 0 0.05
      }
      device [
        RotationalMotor {
          name "wheel1"
        }
      ]
      endPoint Solid {
        translation 0.060000000000000026 1.966348654079034e-17 0.049999999999999996
        rotation -0.6402252936442611 0.639715667975515 0.42529453032546766 2.3367787162475726
        children [
          DEF Wheel Shape {
            appearance PBRAppearance {
              baseColor 1 0 0
              metalness 0
            }
            geometry Cylinder {
              height 0.02
              radius 0.04
            }
          }
        ]
        boundingObject USE Wheel
        physics DEF Physics_wh Physics {
        }
      }
    }
    HingeJoint {
      jointParameters HingeJointParameters {
        position 40376.02934996766
        anchor -0.06 0 0.05
      }
      device [
        RotationalMotor {
          name "wheel2"
        }
      ]
      endPoint Solid {
        translation -0.06 -1.8798564439703023e-17 0.05
        rotation 0.138584461505872 -0.13847414690322596 0.9806218729299033 1.5895672418594027
        children [
          USE Wheel
        ]
        name "solid(1)"
        boundingObject USE Wheel
        physics USE Physics_wh
      }
    }
    HingeJoint {
      jointParameters HingeJointParameters {
        position 43816.966465960424
        anchor 0.06 0 -0.05
      }
      device [
        RotationalMotor {
          name "wheel3"
        }
      ]
      endPoint Solid {
        translation 0.060000000000000026 -1.9663115887938432e-17 -0.049999999999999996
        rotation -0.6401897561451252 0.6396801587645805 0.4254014229051969 2.3365975836789734
        children [
          USE Wheel
        ]
        name "solid(2)"
        boundingObject USE Wheel
        physics USE Physics_wh
      }
    }
    HingeJoint {
      jointParameters HingeJointParameters {
        position 40376.02969237119
        anchor -0.06 0 -0.05
      }
      device [
        RotationalMotor {
          name "wheel4"
        }
      ]
      endPoint Solid {
        translation -0.06 -1.2157228990397642e-08 -0.05000000350782252
        rotation 0.13874912301540315 -0.13863867734056418 0.9805753403016595 1.589614686766645
        children [
          USE Wheel
        ]
        name "solid(3)"
        boundingObject USE Wheel
        physics USE Physics_wh
      }
    }
    DistanceSensor {
      translation 0.02 0 0.1
      rotation 0 1 0 -1.27
      children [
        DEF sensor Shape {
          appearance PBRAppearance {
            baseColor 0 1 1
            metalness 0
          }
          geometry Box {
            size 0.01 0.01 0.01
          }
        }
      ]
      name "ds_left"
      boundingObject USE sensor
      physics Physics {
      }
    }
    DistanceSensor {
      translation -0.02 0 0.1
      rotation 0 1 0 -1.87
      children [
        DEF sensor Shape {
          appearance PBRAppearance {
            baseColor 0 1 1
            metalness 0
          }
          geometry Box {
            size 0.01 0.01 0.01
          }
        }
      ]
      name "ds_right"
      boundingObject USE sensor
      physics Physics {
      }
    }
    GPS {
      translation 0 0.03 0
      children [
        Solid {
          children [
            Shape {
              appearance PBRAppearance {
              }
              geometry Cylinder {
                height 0.02
                radius 0.01
              }
            }
          ]
        }
      ]
      name "global"
    }
    InertialUnit {
      translation 0 0.03 0.04
      children [
        Shape {
          appearance PBRAppearance {
            baseColor 0 0 0.7
            metalness 0
          }
          geometry Box {
            size 0.02 0.02 0.02
          }
        }
      ]
      name "imu"
    }
  ]
  name "robot0_name"
  boundingObject USE Body
  physics Physics {
  }
  controller "robot_controller"
  controllerArgs [
    "0"
  ]
}
DEF robot1 Robot {
  translation 1.6 0.0408799 0.61777
  rotation 0.9999589468593014 0.0014500888085057803 -0.008944374683799338 -0.0005175336905305816
  children [
    Receiver {
      channel 1
    }
    DEF Body Shape {
      appearance PBRAppearance {
        baseColor 0 1 0
        metalness 0
      }
      geometry Box {
        size 0.1 0.05 0.2
      }
    }
    HingeJoint {
      jointParameters HingeJointParameters {
        position 43816.96618303253
        anchor 0.06 0 0.05
      }
      device [
        RotationalMotor {
          name "wheel1"
        }
      ]
      endPoint Solid {
        translation 0.060000000000000026 1.9663486540790575e-17 0.049999999999999996
        rotation -0.6402252936442612 0.639715667975515 0.42529453032546766 2.336778716247573
        children [
          DEF Wheel Shape {
            appearance PBRAppearance {
              baseColor 1 0 0
              metalness 0
            }
            geometry Cylinder {
              height 0.02
              radius 0.04
            }
          }
        ]
        boundingObject USE Wheel
        physics DEF Physics_wh Physics {
        }
      }
    }
    HingeJoint {
      jointParameters HingeJointParameters {
        position 40376.02934996766
        anchor -0.06 0 0.05
      }
      device [
        RotationalMotor {
          name "wheel2"
        }
      ]
      endPoint Solid {
        translation -0.06 -1.8798564239560543e-17 0.05
        rotation 0.13858446150587178 -0.13847414690322593 0.9806218729299033 1.5895672418594027
        children [
          USE Wheel
        ]
        name "solid(1)"
        boundingObject USE Wheel
        physics USE Physics_wh
      }
    }
    HingeJoint {
      jointParameters HingeJointParameters {
        position 43816.966465960424
        anchor 0.06 0 -0.05
      }
      device [
        RotationalMotor {
          name "wheel3"
        }
      ]
      endPoint Solid {
        translation 0.060000000000000026 -1.9663115887938672e-17 -0.049999999999999996
        rotation -0.6401897561451252 0.6396801587645804 0.42540142290519695 2.336597583678973
        children [
          USE Wheel
        ]
        name "solid(2)"
        boundingObject USE Wheel
        physics USE Physics_wh
      }
    }
    HingeJoint {
      jointParameters HingeJointParameters {
        position 40376.02969237119
        anchor -0.06 0 -0.05
      }
      device [
        RotationalMotor {
          name "wheel4"
        }
      ]
      endPoint Solid {
        translation -0.06 -1.2157228990720165e-08 -0.05000000350782252
        rotation 0.13874912301540335 -0.1386386773405642 0.9805753403016595 1.589614686766645
        children [
          USE Wheel
        ]
        name "solid(3)"
        boundingObject USE Wheel
        physics USE Physics_wh
      }
    }
    DistanceSensor {
      translation 0.02 0 0.1
      rotation 0 1 0 -1.27
      children [
        DEF sensor Shape {
          appearance PBRAppearance {
            baseColor 0 1 1
            metalness 0
          }
          geometry Box {
            size 0.01 0.01 0.01
          }
        }
      ]
      name "ds_left"
      boundingObject USE sensor
      physics Physics {
      }
    }
    DistanceSensor {
      translation -0.02 0 0.1
      rotation 0 1 0 -1.87
      children [
        DEF sensor Shape {
          appearance PBRAppearance {
            baseColor 0 1 1
            metalness 0
          }
          geometry Box {
            size 0.01 0.01 0.01
          }
        }
      ]
      name "ds_right"
      boundingObject USE sensor
      physics Physics {
      }
    }
    GPS {
      translation 0 0.03 0
      children [
        Solid {
          children [
            Shape {
              appearance PBRAppearance {
              }
              geometry Cylinder {
                height 0.02
                radius 0.01
              }
            }
          ]
        }
      ]
      name "global"
    }
    InertialUnit {
      translation 0 0.03 0.04
      children [
        Shape {
          appearance PBRAppearance {
            baseColor 0 0 0.7
            metalness 0
          }
          geometry Box {
            size 0.02 0.02 0.02
          }
        }
      ]
      name "imu"
    }
  ]
  name "robot1_name"
  boundingObject USE Body
  physics Physics {
  }
  controller "robot_controller"
  controllerArgs [
    "1"
  ]
}
DEF robot2 Robot {
  translation 1.6 0.0402351 -0.63223
  rotation 0.9999589468593021 0.0014500888083333757 -0.00894437468375058 -0.0005175336905303378
  children [
    Receiver {
      channel 2
    }
    DEF Body Shape {
      appearance PBRAppearance {
        baseColor 0 1 0
        metalness 0
      }
      geometry Box {
        size 0.1 0.05 0.2
      }
    }
    HingeJoint {
      jointParameters HingeJointParameters {
        position 43816.96618303253
        anchor 0.06 0 0.05
      }
      device [
        RotationalMotor {
          name "wheel1"
        }
      ]
      endPoint Solid {
        translation 0.060000000000000026 1.6751389819088997e-17 0.04999999999999999
        rotation -0.6402252936442614 0.6397156679755148 0.42529453032546766 2.336778716247572
        children [
          DEF Wheel Shape {
            appearance PBRAppearance {
              baseColor 1 0 0
              metalness 0
            }
            geometry Cylinder {
              height 0.02
              radius 0.04
            }
          }
        ]
        boundingObject USE Wheel
        physics DEF Physics_wh Physics {
        }
      }
    }
    HingeJoint {
      jointParameters HingeJointParameters {
        position 40376.02934996766
        anchor -0.06 0 0.05
      }
      device [
        RotationalMotor {
          name "wheel2"
        }
      ]
      endPoint Solid {
        translation -0.06 2.447938127919258e-18 0.05000000000000001
        rotation 0.13858446150587236 -0.13847414690322657 0.9806218729299031 1.5895672418594016
        children [
          USE Wheel
        ]
        name "solid(1)"
        boundingObject USE Wheel
        physics USE Physics_wh
      }
    }
    HingeJoint {
      jointParameters HingeJointParameters {
        position 43816.966465960424
        anchor 0.06 0 -0.05
      }
      device [
        RotationalMotor {
          name "wheel3"
        }
      ]
      endPoint Solid {
        translation 0.060000000000000026 -1.6753327871470865e-17 -0.04999999999999999
        rotation -0.6401897561451254 0.6396801587645803 0.42540142290519656 2.336597583678972
        children [
          USE Wheel
        ]
        name "solid(2)"
        boundingObject USE Wheel
        physics USE Physics_wh
      }
    }
    HingeJoint {
      jointParameters HingeJointParameters {
        position 40376.02969237119
        anchor -0.06 0 -0.05
      }
      device [
        RotationalMotor {
          name "wheel4"
        }
      ]
      endPoint Solid {
        translation -0.06 -1.215722899639598e-08 -0.05000000350782252
        rotation 0.13874912301540376 -0.13863867734056443 0.9805753403016595 1.5896146867666434
        children [
          USE Wheel
        ]
        name "solid(3)"
        boundingObject USE Wheel
        physics USE Physics_wh
      }
    }
    DistanceSensor {
      translation 0.02 0 0.1
      rotation 0 1 0 -1.27
      children [
        DEF sensor Shape {
          appearance PBRAppearance {
            baseColor 0 1 1
            metalness 0
          }
          geometry Box {
            size 0.01 0.01 0.01
          }
        }
      ]
      name "ds_left"
      boundingObject USE sensor
      physics Physics {
      }
    }
    DistanceSensor {
      translation -0.02 0 0.1
      rotation 0 1 0 -1.87
      children [
        DEF sensor Shape {
          appearance PBRAppearance {
            baseColor 0 1 1
            metalness 0
          }
          geometry Box {
            size 0.01 0.01 0.01
          }
        }
      ]
      name "ds_right"
      boundingObject USE sensor
      physics Physics {
      }
    }
    GPS {
      translation 0 0.03 0
      children [
        Solid {
          children [
            Shape {
              appearance PBRAppearance {
              }
              geometry Cylinder {
                height 0.02
                radius 0.01
              }
            }
          ]
        }
      ]
      name "global"
    }
    InertialUnit {
      translation 0 0.03 0.04
      children [
        Shape {
          appearance PBRAppearance {
            baseColor 0 0 0.7
            metalness 0
          }
          geometry Box {
            size 0.02 0.02 0.02
          }
        }
      ]
      name "imu"
    }
  ]
  name "robot2_name"
  boundingObject USE Body
  physics Physics {
  }
  controller "robot_controller"
  controllerArgs [
    "2"
  ]
}
DEF robot3 Robot {
  translation 1.6 0.0397251 -1.61223
  rotation 0.999958946859302 0.0014500888084978607 -0.008944374683744087 -0.0005175336905306209
  children [
    Receiver {
      channel 3
    }
    DEF Body Shape {
      appearance PBRAppearance {
        baseColor 0 1 0
        metalness 0
      }
      geometry Box {
        size 0.1 0.05 0.2
      }
    }
    HingeJoint {
      jointParameters HingeJointParameters {
        position 43816.96618303253
        anchor 0.06 0 0.05
      }
      device [
        RotationalMotor {
          name "wheel1"
        }
      ]
      endPoint Solid {
        translation 0.060000000000000026 1.9663486321928956e-17 0.049999999999999996
        rotation -0.6402252936442611 0.639715667975515 0.42529453032546766 2.3367787162475726
        children [
          DEF Wheel Shape {
            appearance PBRAppearance {
              baseColor 1 0 0
              metalness 0
            }
            geometry Cylinder {
              height 0.02
              radius 0.04
            }
          }
        ]
        boundingObject USE Wheel
        physics DEF Physics_wh Physics {
        }
      }
    }
    HingeJoint {
      jointParameters HingeJointParameters {
        position 40376.02934996766
        anchor -0.06 0 0.05
      }
      device [
        RotationalMotor {
          name "wheel2"
        }
      ]
      endPoint Solid {
        translation -0.06 -1.891870861978187e-17 0.05
        rotation 0.13858446150587198 -0.13847414690322593 0.9806218729299033 1.5895672418594027
        children [
          USE Wheel
        ]
        name "solid(1)"
        boundingObject USE Wheel
        physics USE Physics_wh
      }
    }
    HingeJoint {
      jointParameters HingeJointParameters {
        position 43816.966465960424
        anchor 0.06 0 -0.05
      }
      device [
        RotationalMotor {
          name "wheel3"
        }
      ]
      endPoint Solid {
        translation 0.060000000000000026 -1.966311567140485e-17 -0.049999999999999996
        rotation -0.6401897561451253 0.6396801587645804 0.42540142290519695 2.336597583678973
        children [
          USE Wheel
        ]
        name "solid(2)"
        boundingObject USE Wheel
        physics USE Physics_wh
      }
    }
    HingeJoint {
      jointParameters HingeJointParameters {
        position 40376.02969237119
        anchor -0.06 0 -0.05
      }
      device [
        RotationalMotor {
          name "wheel4"
        }
      ]
      endPoint Solid {
        translation -0.06 -1.2157228990560754e-08 -0.05000000350782252
        rotation 0.13874912301540335 -0.1386386773405642 0.9805753403016595 1.589614686766645
        children [
          USE Wheel
        ]
        name "solid(3)"
        boundingObject USE Wheel
        physics USE Physics_wh
      }
    }
    DistanceSensor {
      translation 0.02 0 0.1
      rotation 0 1 0 -1.27
      children [
        DEF sensor Shape {
          appearance PBRAppearance {
            baseColor 0 1 1
            metalness 0
          }
          geometry Box {
            size 0.01 0.01 0.01
          }
        }
      ]
      name "ds_left"
      boundingObject USE sensor
      physics Physics {
      }
    }
    DistanceSensor {
      translation -0.02 0 0.1
      rotation 0 1 0 -1.87
      children [
        DEF sensor Shape {
          appearance PBRAppearance {
            baseColor 0 1 1
            metalness 0
          }
          geometry Box {
            size 0.01 0.01 0.01
          }
        }
      ]
      name "ds_right"
      boundingObject USE sensor
      physics Physics {
      }
    }
    GPS {
      translation 0 0.03 0
      children [
        Solid {
          children [
            Shape {
              appearance PBRAppearance {
              }
              geometry Cylinder {
                height 0.02
                radius 0.01
              }
            }
          ]
        }
      ]
      name "global"
    }
    InertialUnit {
      translation 0 0.03 0.04
      children [
        Shape {
          appearance PBRAppearance {
            baseColor 0 0 0.7
            metalness 0
          }
          geometry Box {
            size 0.02 0.02 0.02
          }
        }
      ]
      name "imu"
    }
  ]
  name "robot3_name"
  boundingObject USE Body
  physics Physics {
  }
  controller "robot_controller"
  controllerArgs [
    "3"
  ]
}
DEF mine0 Robot {
  children [
    Shape {
      appearance PBRAppearance {
        baseColor 1 0 0
      }
      geometry Cylinder {
        height 0.5
        radius 0.05
      }
    }
  ]
  name "mine0_name"
}
DEF mine1 Robot {
  translation 1.61 0 0.91
  children [
    Shape {
      appearance PBRAppearance {
        baseColor 1 0 0
      }
      geometry Cylinder {
        height 0.5
        radius 0.05
      }
    }
  ]
  name "mine1_name"
}
DEF mine2 Robot {
  translation -1.24 0 0.63
  children [
    Shape {
      appearance PBRAppearance {
        baseColor 1 0 0
      }
      geometry Cylinder {
        height 0.5
        radius 0.05
      }
    }
  ]
  name "mine2_name"
}
DEF mine3 Robot {
  translation -1.4 0 -1.35
  children [
    Shape {
      appearance PBRAppearance {
        baseColor 1 0 0
      }
      geometry Cylinder {
        height 0.5
        radius 0.05
      }
    }
  ]
  name "mine3_name"
}
DEF mine4 Robot {
  translation 0.88 0 -0.35
  children [
    Shape {
      appearance PBRAppearance {
        baseColor 1 0 0
      }
      geometry Cylinder {
        height 0.5
        radius 0.05
      }
    }
  ]
  name "mine4_name"
}
DEF mine5 Robot {
  translation -0.37 0 1.36
  children [
    Shape {
      appearance PBRAppearance {
        baseColor 1 0 0
      }
      geometry Cylinder {
        height 0.5
        radius 0.05
      }
    }
  ]
  name "mine5_name"
}
DEF admin Robot {
  translation 0 1.96 0
  children [
    Emitter {
      channel 3
    }
    Shape {
      appearance PBRAppearance {
      }
      geometry Sphere {
        radius 0.1
      }
    }
  ]
  controller "supervisor_controller"
  controllerArgs [
    ""
  ]
  supervisor TRUE
}
