#VRML_SIM R2021a utf8
WorldInfo {
  coordinateSystem "NUE"
}
Viewpoint {
<<<<<<< Updated upstream
  orientation 0.9985715460112334 0.04423684148272677 0.029966136760801964 5.091061125709899
  position -2.904566601525694 17.204711970193895 7.884124999350683
=======
  orientation 0.9993251013187591 0.030818420856925155 0.019989167319759783 5.131772444998734
  position -0.22643457739717449 28.32212485631626 13.463410850641798
>>>>>>> Stashed changes
}
TexturedBackground {
}
TexturedBackgroundLight {
}
RectangleArena {
<<<<<<< Updated upstream
  floorSize 100 100
=======
  translation 0 0 7.79
  floorSize 20 20
>>>>>>> Stashed changes
  wallThickness 0.1
  wallHeight 0.5
}
DEF robot0 Robot {
  translation -5.40182 0.0397206 -0.526351
  rotation 1.3736399998669196e-05 0.9999999999031184 2.252719999781753e-06 1.5708
  children [
    Emitter {
      channel -1
    }
    Receiver {
      channel -1
    }
    DEF Body Shape {
      appearance PBRAppearance {
        baseColor 0 1 0
        metalness 0
      }
      geometry Box {
        size 0.1 0.05 0.2
      }
    }
    HingeJoint {
      jointParameters HingeJointParameters {
        position 43884.96607707316
        anchor 0.06 0 0.05
      }
      device [
        RotationalMotor {
          name "wheel1"
        }
      ]
      endPoint Solid {
<<<<<<< Updated upstream
        translation 0.060000000000000026 -3.576084869377188e-18 0.04999999999999998
=======
        translation 0.060000000000000026 -3.765163118931336e-18 0.04999999999999998
>>>>>>> Stashed changes
        rotation 0.7072380854001235 -0.7066751168860492 -0.02060508999389237 3.1828298187646387
        children [
          DEF Wheel Shape {
            appearance PBRAppearance {
              baseColor 1 0 0
              metalness 0
            }
            geometry Cylinder {
              height 0.02
              radius 0.04
            }
          }
        ]
        boundingObject USE Wheel
        physics DEF Physics_wh Physics {
        }
      }
    }
    HingeJoint {
      jointParameters HingeJointParameters {
        position 40411.70945349283
        anchor -0.06 0 0.05
      }
      device [
        RotationalMotor {
          name "wheel2"
        }
      ]
      endPoint Solid {
        translation -0.06 1.0560456843632646e-17 0.050000000000000024
        rotation -0.6073142906920832 0.6068308625073404 0.5127627683732207 2.193334637453841
        children [
          USE Wheel
        ]
        name "solid(1)"
        boundingObject USE Wheel
        physics USE Physics_wh
      }
    }
    HingeJoint {
      jointParameters HingeJointParameters {
        position 43884.966362714615
        anchor 0.06 0 -0.05
      }
      device [
        RotationalMotor {
          name "wheel3"
        }
      ]
      endPoint Solid {
<<<<<<< Updated upstream
        translation 0.060000000000000026 3.5729659881802e-18 -0.04999999999999998
=======
        translation 0.060000000000000026 3.7639379047333056e-18 -0.04999999999999998
>>>>>>> Stashed changes
        rotation 0.7072366097480942 -0.7066736424086548 -0.02070606087372919 3.183031835071632
        children [
          USE Wheel
        ]
        name "solid(2)"
        boundingObject USE Wheel
        physics USE Physics_wh
      }
    }
    HingeJoint {
      jointParameters HingeJointParameters {
        position 40411.709798414995
        anchor -0.06 0 -0.05
      }
      device [
        RotationalMotor {
          name "wheel4"
        }
      ]
      endPoint Solid {
        translation -0.06 2.107030821802262e-09 -0.0499999875234838
        rotation -0.6072584616914315 0.6067750779471254 0.5128948873662286 2.193125324605423
        children [
          USE Wheel
        ]
        name "solid(3)"
        boundingObject USE Wheel
        physics USE Physics_wh
      }
    }
    DistanceSensor {
      translation 0.02 0 0.1
      rotation 0 1 0 -1.27
      children [
        DEF sensor Shape {
          appearance PBRAppearance {
            baseColor 0 1 1
            metalness 0
          }
          geometry Box {
            size 0.01 0.01 0.01
          }
        }
      ]
      name "ds_left"
      boundingObject USE sensor
      physics Physics {
      }
    }
    DistanceSensor {
      translation -0.02 0 0.1
      rotation 0 1 0 -1.87
      children [
        DEF sensor Shape {
          appearance PBRAppearance {
            baseColor 0 1 1
            metalness 0
          }
          geometry Box {
            size 0.01 0.01 0.01
          }
        }
      ]
      name "ds_right"
      boundingObject USE sensor
      physics Physics {
      }
    }
    GPS {
      translation 0 0.03 0
      children [
        Solid {
          children [
            Shape {
              appearance PBRAppearance {
              }
              geometry Cylinder {
                height 0.02
                radius 0.01
              }
            }
          ]
        }
      ]
      name "global"
    }
    InertialUnit {
      translation 0 0.03 0.04
      children [
        Shape {
          appearance PBRAppearance {
            baseColor 0 0 0.7
            metalness 0
          }
          geometry Box {
            size 0.02 0.02 0.02
          }
        }
      ]
      name "imu"
    }
  ]
  name "robot0_name"
  boundingObject USE Body
  physics Physics {
  }
  controller "robot_controller_v2"
  controllerArgs [
    "0"
  ]
  supervisor TRUE
}
DEF robot1 Robot {
  translation -5.37296 0.0397206 1.54848
  rotation -8.328909999539522e-06 0.9999999999447133 6.41891999964512e-06 -1.850055307179586
  children [
    Emitter {
      channel -1
    }
    Receiver {
      channel -1
    }
    DEF Body Shape {
      appearance PBRAppearance {
        baseColor 0 1 0
        metalness 0
      }
      geometry Box {
        size 0.1 0.05 0.2
      }
    }
    HingeJoint {
      jointParameters HingeJointParameters {
        position 43860.55013201445
        anchor 0.06 0 0.05
      }
      device [
        RotationalMotor {
          name "wheel1"
        }
      ]
      endPoint Solid {
<<<<<<< Updated upstream
        translation 0.060000000000000026 2.25013348587894e-17 0.049999999999999996
        rotation 0.6796648066178624 -0.6791237867065351 -0.2772122525691826 3.682846307860758
=======
        translation 0.060000000000000026 -2.244419343582714e-17 0.049999999999999996
        rotation 0.5392933390244742 -0.5388640561903215 0.647138488601897 1.9921441284262609
>>>>>>> Stashed changes
        children [
          DEF Wheel Shape {
            appearance PBRAppearance {
              baseColor 1 0 0
              metalness 0
            }
            geometry Cylinder {
              height 0.02
              radius 0.04
            }
          }
        ]
        boundingObject USE Wheel
        physics DEF Physics_wh Physics {
        }
      }
    }
    HingeJoint {
      jointParameters HingeJointParameters {
        position 40410.205400467356
        anchor -0.06 0 0.05
      }
      device [
        RotationalMotor {
          name "wheel2"
        }
      ]
      endPoint Solid {
<<<<<<< Updated upstream
        translation -0.06 2.271303376261999e-17 0.049999999999999996
        rotation -0.7069381579568204 0.7063754281879598 -0.0356678465413077 3.212954875656009
=======
        translation -0.06 -1.340748311504556e-17 0.050000000000000024
        rotation -0.33034028161932044 0.33007732748644486 0.8842648111392167 1.692695681702468
>>>>>>> Stashed changes
        children [
          USE Wheel
        ]
        name "solid(1)"
        boundingObject USE Wheel
        physics USE Physics_wh
      }
    }
    HingeJoint {
      jointParameters HingeJointParameters {
        position 43860.550415271915
        anchor 0.06 0 -0.05
      }
      device [
        RotationalMotor {
          name "wheel3"
        }
      ]
      endPoint Solid {
        translation 0.060000000000000026 -2.2497868079980914e-17 -0.049999999999999996
        rotation 0.6796436605486997 -0.6791026574698535 -0.277315840321729 3.683038824998462
        children [
          USE Wheel
        ]
        name "solid(2)"
        boundingObject USE Wheel
        physics USE Physics_wh
      }
    }
    HingeJoint {
      jointParameters HingeJointParameters {
        position 40410.205743393555
        anchor -0.06 0 -0.05
      }
      device [
        RotationalMotor {
          name "wheel4"
        }
      ]
      endPoint Solid {
<<<<<<< Updated upstream
        translation -0.06 1.2589260425854799e-08 -0.050000001270258866
        rotation -0.7069412122420559 0.7063784800419531 -0.035546664644558815 3.212712626416847
=======
        translation -0.06 -9.561144808812592e-09 -0.049999991712205025
        rotation -0.33020502110644734 0.3299421746422811 0.8843657645049435 1.6925823681196934
>>>>>>> Stashed changes
        children [
          USE Wheel
        ]
        name "solid(3)"
        boundingObject USE Wheel
        physics USE Physics_wh
      }
    }
    DistanceSensor {
      translation 0.02 0 0.1
      rotation 0 1 0 -1.27
      children [
        DEF sensor Shape {
          appearance PBRAppearance {
            baseColor 0 1 1
            metalness 0
          }
          geometry Box {
            size 0.01 0.01 0.01
          }
        }
      ]
      name "ds_left"
      boundingObject USE sensor
      physics Physics {
      }
    }
    DistanceSensor {
      translation -0.02 0 0.1
      rotation 0 1 0 -1.87
      children [
        DEF sensor Shape {
          appearance PBRAppearance {
            baseColor 0 1 1
            metalness 0
          }
          geometry Box {
            size 0.01 0.01 0.01
          }
        }
      ]
      name "ds_right"
      boundingObject USE sensor
      physics Physics {
      }
    }
    GPS {
      translation 0 0.03 0
      children [
        Solid {
          children [
            Shape {
              appearance PBRAppearance {
              }
              geometry Cylinder {
                height 0.02
                radius 0.01
              }
            }
          ]
        }
      ]
      name "global"
    }
    InertialUnit {
      translation 0 0.03 0.04
      children [
        Shape {
          appearance PBRAppearance {
            baseColor 0 0 0.7
            metalness 0
          }
          geometry Box {
            size 0.02 0.02 0.02
          }
        }
      ]
      name "imu"
    }
  ]
  name "robot1_name"
  boundingObject USE Body
  physics Physics {
  }
  controller "robot_controller_v2"
  controllerArgs [
    "1"
  ]
  supervisor TRUE
}
DEF robot2 Robot {
  translation -5.446453666353835 0.03972057931461059 -1.6263097249169127
  rotation -1.0752699999127208e-05 0.9999999999188305 6.8350799994452005e-06 -1.344635307179586
  children [
    Emitter {
      channel -1
    }
    Receiver {
      channel -1
    }
    DEF Body Shape {
      appearance PBRAppearance {
        baseColor 0 1 0
        metalness 0
      }
      geometry Box {
        size 0.1 0.05 0.2
      }
    }
    HingeJoint {
      jointParameters HingeJointParameters {
        position 43896.26205198756
        anchor 0.06 0 0.05
      }
      device [
        RotationalMotor {
          name "wheel1"
        }
      ]
      endPoint Solid {
<<<<<<< Updated upstream
        translation 0.060000000000000026 -1.9763148056573656e-17 0.049999999999999996
        rotation 0.6352611087291231 -0.6347554346006865 0.4399191539148292 2.3121271851090697
=======
        translation 0.060000000000000026 1.5898904633425468e-17 0.04999999999999999
        rotation 0.6580162906112149 -0.65749250313284 -0.3670397384676071 3.845655200995858
>>>>>>> Stashed changes
        children [
          DEF Wheel Shape {
            appearance PBRAppearance {
              baseColor 1 0 0
              metalness 0
            }
            geometry Cylinder {
              height 0.02
              radius 0.04
            }
          }
        ]
        boundingObject USE Wheel
        physics DEF Physics_wh Physics {
        }
      }
    }
    HingeJoint {
      jointParameters HingeJointParameters {
        position 40421.213479189086
        anchor -0.06 0 0.05
      }
      device [
        RotationalMotor {
          name "wheel2"
        }
      ]
      endPoint Solid {
        translation -0.06 -6.964937309979875e-18 0.05
        rotation -0.5598773699301796 0.5594317020037495 -0.6112065947233006 4.239539314480346
        children [
          USE Wheel
        ]
        name "solid(1)"
        boundingObject USE Wheel
        physics USE Physics_wh
      }
    }
    HingeJoint {
      jointParameters HingeJointParameters {
        position 43896.26233693391
        anchor 0.06 0 -0.05
      }
      device [
        RotationalMotor {
          name "wheel3"
        }
      ]
      endPoint Solid {
<<<<<<< Updated upstream
        translation 0.060000000000000026 1.976354320475162e-17 -0.049999999999999996
        rotation 0.6352985155151432 -0.6347928116105357 0.4398111896164609 2.312308205772405
=======
        translation 0.060000000000000026 -1.590006192122937e-17 -0.04999999999999999
        rotation 0.6579867320020357 -0.6574629680526074 -0.3671456198141787 3.8458419293246364
>>>>>>> Stashed changes
        children [
          USE Wheel
        ]
        name "solid(2)"
        boundingObject USE Wheel
        physics USE Physics_wh
      }
    }
    HingeJoint {
      jointParameters HingeJointParameters {
        position 40421.21382308281
        anchor -0.06 0 -0.05
      }
      device [
        RotationalMotor {
          name "wheel4"
        }
      ]
      endPoint Solid {
<<<<<<< Updated upstream
        translation -0.06 -1.112729885349771e-09 -0.05000001260416074
        rotation -0.5599495139103449 0.5595037885565904 -0.6110745064739573 4.239346905452836
=======
        translation -0.06 -1.9246431069749137e-09 -0.04999998749405004
        rotation -0.5459482187494367 0.5455136385651741 0.6358894656964381 2.0080880870726157
>>>>>>> Stashed changes
        children [
          USE Wheel
        ]
        name "solid(3)"
        boundingObject USE Wheel
        physics USE Physics_wh
      }
    }
    DistanceSensor {
      translation 0.02 0 0.1
      rotation 0 1 0 -1.27
      children [
        DEF sensor Shape {
          appearance PBRAppearance {
            baseColor 0 1 1
            metalness 0
          }
          geometry Box {
            size 0.01 0.01 0.01
          }
        }
      ]
      name "ds_left"
      boundingObject USE sensor
      physics Physics {
      }
    }
    DistanceSensor {
      translation -0.02 0 0.1
      rotation 0 1 0 -1.87
      children [
        DEF sensor Shape {
          appearance PBRAppearance {
            baseColor 0 1 1
            metalness 0
          }
          geometry Box {
            size 0.01 0.01 0.01
          }
        }
      ]
      name "ds_right"
      boundingObject USE sensor
      physics Physics {
      }
    }
    GPS {
      translation 0 0.03 0
      children [
        Solid {
          children [
            Shape {
              appearance PBRAppearance {
              }
              geometry Cylinder {
                height 0.02
                radius 0.01
              }
            }
          ]
        }
      ]
      name "global"
    }
    InertialUnit {
      translation 0 0.03 0.04
      children [
        Shape {
          appearance PBRAppearance {
            baseColor 0 0 0.7
            metalness 0
          }
          geometry Box {
            size 0.02 0.02 0.02
          }
        }
      ]
      name "imu"
    }
  ]
  name "robot2_name"
  boundingObject USE Body
  physics Physics {
  }
  controller "robot_controller_v2"
  controllerArgs [
    "2"
  ]
  supervisor TRUE
}
DEF robot3 Robot {
  translation -5.21249 0.0397206 3.61829
  rotation 7.025569999801596e-06 0.9999999999717597 -2.668669999924636e-06 1.8558
  children [
    Emitter {
      channel -1
    }
    Receiver {
      channel -1
    }
    DEF Body Shape {
      appearance PBRAppearance {
        baseColor 0 1 0
        metalness 0
      }
      geometry Box {
        size 0.1 0.05 0.2
      }
    }
    HingeJoint {
      jointParameters HingeJointParameters {
        position 43883.97411442267
        anchor 0.06 0 0.05
      }
      device [
        RotationalMotor {
          name "wheel1"
        }
      ]
      endPoint Solid {
        translation 0.060000000000000026 -1.1341892362420387e-17 0.04999999999999998
        rotation 0.6663695508776137 -0.6658391141214117 0.33557397957705426 2.493580583817602
        children [
          DEF Wheel Shape {
            appearance PBRAppearance {
              baseColor 1 0 0
              metalness 0
            }
            geometry Cylinder {
              height 0.02
              radius 0.04
            }
          }
        ]
        boundingObject USE Wheel
        physics DEF Physics_wh Physics {
        }
      }
    }
    HingeJoint {
      jointParameters HingeJointParameters {
        position 40420.38141767931
        anchor -0.06 0 0.05
      }
      device [
        RotationalMotor {
          name "wheel2"
        }
      ]
      endPoint Solid {
<<<<<<< Updated upstream
        translation -0.06 -2.2322824752102388e-17 0.049999999999999996
        rotation -0.3045361840316171 0.3042937702157538 -0.9025868456959381 4.610869771116894
=======
        translation -0.06 1.3874592435852657e-17 0.050000000000000024
        rotation 0.6282482371842046 -0.6277481453709124 -0.45960463276420443 4.003821890932696
>>>>>>> Stashed changes
        children [
          USE Wheel
        ]
        name "solid(1)"
        boundingObject USE Wheel
        physics USE Physics_wh
      }
    }
    HingeJoint {
      jointParameters HingeJointParameters {
        position 43883.97439830295
        anchor 0.06 0 -0.05
      }
      device [
        RotationalMotor {
          name "wheel3"
        }
      ]
      endPoint Solid {
        translation 0.060000000000000026 1.1339623806390273e-17 -0.04999999999999998
        rotation 0.6663960477424486 -0.6658655898944812 0.335468811885276 2.493769756750608
        children [
          USE Wheel
        ]
        name "solid(2)"
        boundingObject USE Wheel
        physics USE Physics_wh
      }
    }
    HingeJoint {
      jointParameters HingeJointParameters {
        position 40420.381760841774
        anchor -0.06 0 -0.05
      }
      device [
        RotationalMotor {
          name "wheel4"
        }
      ]
      endPoint Solid {
        translation -0.06 -1.0067787222912565e-08 -0.05000000766437837
        rotation -0.3046766825104675 0.3044341568564225 -0.9024920848813773 4.61076531870655
        children [
          USE Wheel
        ]
        name "solid(3)"
        boundingObject USE Wheel
        physics USE Physics_wh
      }
    }
    DistanceSensor {
      translation 0.02 0 0.1
      rotation 0 1 0 -1.27
      children [
        DEF sensor Shape {
          appearance PBRAppearance {
            baseColor 0 1 1
            metalness 0
          }
          geometry Box {
            size 0.01 0.01 0.01
          }
        }
      ]
      name "ds_left"
      boundingObject USE sensor
      physics Physics {
      }
    }
    DistanceSensor {
      translation -0.02 0 0.1
      rotation 0 1 0 -1.87
      children [
        DEF sensor Shape {
          appearance PBRAppearance {
            baseColor 0 1 1
            metalness 0
          }
          geometry Box {
            size 0.01 0.01 0.01
          }
        }
      ]
      name "ds_right"
      boundingObject USE sensor
      physics Physics {
      }
    }
    GPS {
      translation 0 0.03 0
      children [
        Solid {
          children [
            Shape {
              appearance PBRAppearance {
              }
              geometry Cylinder {
                height 0.02
                radius 0.01
              }
            }
          ]
        }
      ]
      name "global"
    }
    InertialUnit {
      translation 0 0.03 0.04
      children [
        Shape {
          appearance PBRAppearance {
            baseColor 0 0 0.7
            metalness 0
          }
          geometry Box {
            size 0.02 0.02 0.02
          }
        }
      ]
      name "imu"
    }
  ]
  name "robot3_name"
  boundingObject USE Body
  physics Physics {
  }
  controller "robot_controller_v2"
  controllerArgs [
    "3"
  ]
  supervisor TRUE
}
DEF mine0 Robot {
  children [
    Shape {
      appearance PBRAppearance {
        baseColor 1 0 0
      }
      geometry Cylinder {
        height 0.5
        radius 0.05
      }
    }
  ]
  name "mine0_name"
}
DEF mine1 Robot {
  translation 1.61 0 0.91
  children [
    Shape {
      appearance PBRAppearance {
        baseColor 1 0 0
      }
      geometry Cylinder {
        height 0.5
        radius 0.05
      }
    }
  ]
  name "mine1_name"
}
DEF mine2 Robot {
  translation 2.43 0 -1.3
  children [
    Shape {
      appearance PBRAppearance {
        baseColor 1 0 0
      }
      geometry Cylinder {
        height 0.5
        radius 0.05
      }
    }
  ]
  name "mine2_name"
}
DEF mine3 Robot {
  translation 0 0 -1
  children [
    Shape {
      appearance PBRAppearance {
        baseColor 1 0 0
      }
      geometry Cylinder {
        height 0.5
        radius 0.05
      }
    }
  ]
  name "mine3_name"
}
DEF mine4 Robot {
  translation 0 0 -2
  children [
    Shape {
      appearance PBRAppearance {
        baseColor 1 0 0
      }
      geometry Cylinder {
        height 0.5
        radius 0.05
      }
    }
  ]
  name "mine4_name"
}
DEF mine5 Robot {
  translation -0.0844319 0 0.997765
  children [
    Shape {
      appearance PBRAppearance {
        baseColor 1 0 0
      }
      geometry Cylinder {
        height 0.5
        radius 0.05
      }
    }
  ]
  name "mine5_name"
}
