#VRML_SIM R2021a utf8
WorldInfo {
  coordinateSystem "NUE"
}
Viewpoint {
  orientation 0.9996692117207936 0.02212002911622303 0.013121411868562893 5.212098615312285
  position -1.8022949005274291 10.118422296023352 6.46821955416228
}
TexturedBackground {
}
TexturedBackgroundLight {
}
RectangleArena {
  floorSize 20 20
  floorTileSize 40 40
  wallThickness 0.1
  wallHeight 0.5
}
DEF robot0 Robot {
  translation -0.45701 0.0397215 0.51684
  rotation 1.3736399998669196e-05 0.9999999999031184 2.252719999781753e-06 0
  children [
    DistanceSensor {
      translation 0.05 0.02 -0.096
      rotation 0 -1 0 0
      children [
        DEF sensor Shape {
          appearance PBRAppearance {
            baseColor 0 1 1
            metalness 0
          }
          geometry Box {
            size 0.01 0.01 0.01
          }
        }
      ]
      name "ds_back_left"
      boundingObject USE sensor
      physics Physics {
      }
    }
    Emitter {
      channel -1
    }
    Receiver {
      channel -1
    }
    DEF Body Shape {
      appearance PBRAppearance {
        baseColor 0 1 0
        metalness 0
      }
      geometry Box {
        size 0.1 0.05 0.2
      }
    }
    HingeJoint {
      jointParameters HingeJointParameters {
        position 43884.96607707316
        anchor 0.06 0 0.05
      }
      device [
        RotationalMotor {
          name "wheel1"
        }
      ]
      endPoint Solid {
        translation 0.060000000000000026 -3.4224966346282488e-18 0.04999999999999998
        rotation 0.7072380854001235 -0.7066751168860492 -0.02060508999389237 3.1828298187646387
        children [
          DEF Wheel Shape {
            appearance PBRAppearance {
              baseColor 1 0 0
              metalness 0
            }
            geometry Cylinder {
              height 0.02
              radius 0.04
            }
          }
        ]
        boundingObject USE Wheel
        physics DEF Physics_wh Physics {
        }
      }
    }
    HingeJoint {
      jointParameters HingeJointParameters {
        position 40411.70945349283
        anchor -0.06 0 0.05
      }
      device [
        RotationalMotor {
          name "wheel2"
        }
      ]
      endPoint Solid {
        translation -0.06 1.0560456843632646e-17 0.050000000000000024
        rotation -0.6073142906920832 0.6068308625073404 0.5127627683732207 2.193334637453841
        children [
          USE Wheel
        ]
        name "solid(1)"
        boundingObject USE Wheel
        physics USE Physics_wh
      }
    }
    HingeJoint {
      jointParameters HingeJointParameters {
        position 43884.966362714615
        anchor 0.06 0 -0.05
      }
      device [
        RotationalMotor {
          name "wheel3"
        }
      ]
      endPoint Solid {
        translation 0.060000000000000026 3.4179018074467513e-18 -0.04999999999999998
        rotation 0.7072366097480942 -0.7066736424086548 -0.02070606087372919 3.183031835071632
        children [
          USE Wheel
        ]
        name "solid(2)"
        boundingObject USE Wheel
        physics USE Physics_wh
      }
    }
    HingeJoint {
      jointParameters HingeJointParameters {
        position 40411.709798414995
        anchor -0.06 0 -0.05
      }
      device [
        RotationalMotor {
          name "wheel4"
        }
      ]
      endPoint Solid {
        translation -0.06 2.107030821802262e-09 -0.0499999875234838
        rotation -0.6072584616914315 0.6067750779471254 0.5128948873662286 2.193125324605423
        children [
          USE Wheel
        ]
        name "solid(3)"
        boundingObject USE Wheel
        physics USE Physics_wh
      }
    }
    DistanceSensor {
      translation 0.02 0 0.1
      rotation 0 1 0 -1.27
      children [
        DEF sensor Shape {
          appearance PBRAppearance {
            baseColor 0 1 1
            metalness 0
          }
          geometry Box {
            size 0.01 0.01 0.01
          }
        }
      ]
      name "ds_left"
      boundingObject USE sensor
      physics Physics {
      }
    }
    DistanceSensor {
      translation -0.02 0 0.1
      rotation 0 1 0 -1.87
      children [
        DEF sensor Shape {
          appearance PBRAppearance {
            baseColor 0 1 1
            metalness 0
          }
          geometry Box {
            size 0.01 0.01 0.01
          }
        }
      ]
      name "ds_right"
      boundingObject USE sensor
      physics Physics {
      }
    }
    GPS {
      translation 0 0.03 0
      children [
        Solid {
          children [
            Shape {
              appearance PBRAppearance {
              }
              geometry Cylinder {
                height 0.02
                radius 0.01
              }
            }
          ]
        }
      ]
      name "global"
    }
    InertialUnit {
      translation 0 0.03 0.04
      children [
        Shape {
          appearance PBRAppearance {
            baseColor 0 0 0.7
            metalness 0
          }
          geometry Box {
            size 0.02 0.02 0.02
          }
        }
      ]
      name "imu"
    }
  ]
  name "robot0_name"
  boundingObject USE Body
  physics Physics {
  }
  controller "robot_controller_v2"
  controllerArgs [
    "0"
  ]
  supervisor TRUE
}
Solid {
  translation -3.02472 0.269721 -0.717455
  children [
    Shape {
      appearance PBRAppearance {
      }
      geometry Box {
        size 0.5 0.5 0.5
      }
    }
  ]
  boundingObject Box {
    size 0.5 0.5 0.5
  }
  physics Physics {
    mass 1
  }
}
DEF robot1 Robot {
  translation 0.930987 0.0397206 1.0194
  rotation 0 1 0 4.692820414042842e-06
  children [
    Emitter {
      channel -1
    }
    Receiver {
      channel -1
    }
    DEF Body Shape {
      appearance PBRAppearance {
        baseColor 0 1 0
        metalness 0
      }
      geometry Box {
        size 0.1 0.05 0.2
      }
    }
    HingeJoint {
      jointParameters HingeJointParameters {
        position 43860.55013201445
        anchor 0.06 0 0.05
      }
      device [
        RotationalMotor {
          name "wheel1"
        }
      ]
      endPoint Solid {
        translation 0.060000000000000026 -2.6914896009834985e-17 0.049999999999999996
        rotation 0.5392933390244743 -0.5388640561903215 0.6471384886018969 1.9921441284262607
        children [
          DEF Wheel Shape {
            appearance PBRAppearance {
              baseColor 1 0 0
              metalness 0
            }
            geometry Cylinder {
              height 0.02
              radius 0.04
            }
          }
        ]
        boundingObject USE Wheel
        physics DEF Physics_wh Physics {
        }
      }
    }
    HingeJoint {
      jointParameters HingeJointParameters {
        position 40410.205400467356
        anchor -0.06 0 0.05
      }
      device [
        RotationalMotor {
          name "wheel2"
        }
      ]
      endPoint Solid {
        translation -0.06 -1.0268318877684428e-17 0.050000000000000024
        rotation -0.33034028161932044 0.33007732748644486 0.8842648111392165 1.692695681702468
        children [
          USE Wheel
        ]
        name "solid(1)"
        boundingObject USE Wheel
        physics USE Physics_wh
      }
    }
    HingeJoint {
      jointParameters HingeJointParameters {
        position 43860.550415271915
        anchor 0.06 0 -0.05
      }
      device [
        RotationalMotor {
          name "wheel3"
        }
      ]
      endPoint Solid {
        translation 0.060000000000000026 -2.2659336233887985e-17 -0.049999999999999996
        rotation 0.6796436605486997 -0.6791026574698533 -0.27731584032172896 3.683038824998462
        children [
          USE Wheel
        ]
        name "solid(2)"
        boundingObject USE Wheel
        physics USE Physics_wh
      }
    }
    HingeJoint {
      jointParameters HingeJointParameters {
        position 40410.205743393555
        anchor -0.06 0 -0.05
      }
      device [
        RotationalMotor {
          name "wheel4"
        }
      ]
      endPoint Solid {
        translation -0.06 -9.561144806715095e-09 -0.049999991712205025
        rotation -0.33020502110644745 0.3299421746422811 0.8843657645049434 1.6925823681196934
        children [
          USE Wheel
        ]
        name "solid(3)"
        boundingObject USE Wheel
        physics USE Physics_wh
      }
    }
    DistanceSensor {
      translation 0.02 0 0.1
      rotation 0 1 0 -1.27
      children [
        DEF sensor Shape {
          appearance PBRAppearance {
            baseColor 0 1 1
            metalness 0
          }
          geometry Box {
            size 0.01 0.01 0.01
          }
        }
      ]
      name "ds_left"
      boundingObject USE sensor
      physics Physics {
      }
    }
    DistanceSensor {
      translation -0.02 0 0.1
      rotation 0 1 0 -1.87
      children [
        DEF sensor Shape {
          appearance PBRAppearance {
            baseColor 0 1 1
            metalness 0
          }
          geometry Box {
            size 0.01 0.01 0.01
          }
        }
      ]
      name "ds_right"
      boundingObject USE sensor
      physics Physics {
      }
    }
    DistanceSensor {
      translation 0.05 0.02 -0.096
      rotation 0 -1 0 0
      children [
        DEF sensor Shape {
          appearance PBRAppearance {
            baseColor 0 1 1
            metalness 0
          }
          geometry Box {
            size 0.01 0.01 0.01
          }
        }
      ]
      name "ds_back_left"
      boundingObject USE sensor
      physics Physics {
      }
    }
    GPS {
      translation 0 0.03 0
      children [
        Solid {
          children [
            Shape {
              appearance PBRAppearance {
              }
              geometry Cylinder {
                height 0.02
                radius 0.01
              }
            }
          ]
        }
      ]
      name "global"
    }
    InertialUnit {
      translation 0 0.03 0.04
      children [
        Shape {
          appearance PBRAppearance {
            baseColor 0 0 0.7
            metalness 0
          }
          geometry Box {
            size 0.02 0.02 0.02
          }
        }
      ]
      name "imu"
    }
  ]
  name "robot1_name"
  boundingObject USE Body
  physics Physics {
  }
  controller "robot_controller_v2"
  controllerArgs [
    "1"
  ]
  supervisor TRUE
}
DEF robot2 Robot {
  translation -1.98612 0.0397206 0.898896
  rotation -1.0752699999127208e-05 0.9999999999188305 6.8350799994452005e-06 0
  children [
    DistanceSensor {
      translation 0.08 0.02 -0.096
      rotation 0 -1 0 0
      children [
        DEF sensor Shape {
          appearance PBRAppearance {
            baseColor 0 1 1
            metalness 0
          }
          geometry Box {
            size 0.01 0.01 0.01
          }
        }
      ]
      name "ds_back_left"
      boundingObject USE sensor
      physics Physics {
      }
    }
    Emitter {
      channel -1
    }
    Receiver {
      channel -1
    }
    DEF Body Shape {
      appearance PBRAppearance {
        baseColor 0 1 0
        metalness 0
      }
      geometry Box {
        size 0.1 0.05 0.2
      }
    }
    HingeJoint {
      jointParameters HingeJointParameters {
        position 43896.26205198756
        anchor 0.06 0 0.05
      }
      device [
        RotationalMotor {
          name "wheel1"
        }
      ]
      endPoint Solid {
        translation 0.060000000000000026 1.2613591855627456e-17 0.04999999999999999
        rotation 0.6580162906112148 -0.6574925031328404 -0.3670397384676069 3.845655200995858
        children [
          DEF Wheel Shape {
            appearance PBRAppearance {
              baseColor 1 0 0
              metalness 0
            }
            geometry Cylinder {
              height 0.02
              radius 0.04
            }
          }
        ]
        boundingObject USE Wheel
        physics DEF Physics_wh Physics {
        }
      }
    }
    HingeJoint {
      jointParameters HingeJointParameters {
        position 40421.213479189086
        anchor -0.06 0 0.05
      }
      device [
        RotationalMotor {
          name "wheel2"
        }
      ]
      endPoint Solid {
        translation -0.06 -6.966093569331888e-18 0.05
        rotation -0.5598773699301796 0.5594317020037495 -0.6112065947233006 4.239539314480346
        children [
          USE Wheel
        ]
        name "solid(1)"
        boundingObject USE Wheel
        physics USE Physics_wh
      }
    }
    HingeJoint {
      jointParameters HingeJointParameters {
        position 43896.26233693391
        anchor 0.06 0 -0.05
      }
      device [
        RotationalMotor {
          name "wheel3"
        }
      ]
      endPoint Solid {
        translation 0.060000000000000026 -1.261889468102472e-17 -0.04999999999999999
        rotation 0.6579867320020357 -0.6574629680526075 -0.3671456198141785 3.8458419293246364
        children [
          USE Wheel
        ]
        name "solid(2)"
        boundingObject USE Wheel
        physics USE Physics_wh
      }
    }
    HingeJoint {
      jointParameters HingeJointParameters {
        position 40421.21382308281
        anchor -0.06 0 -0.05
      }
      device [
        RotationalMotor {
          name "wheel4"
        }
      ]
      endPoint Solid {
        translation -0.06 -1.924643109774063e-09 -0.04999998749405004
        rotation -0.5459482187494364 0.5455136385651744 0.6358894656964382 2.0080880870726157
        children [
          USE Wheel
        ]
        name "solid(3)"
        boundingObject USE Wheel
        physics USE Physics_wh
      }
    }
    DistanceSensor {
      translation 0.02 0 0.1
      rotation 0 1 0 -1.27
      children [
        DEF sensor Shape {
          appearance PBRAppearance {
            baseColor 0 1 1
            metalness 0
          }
          geometry Box {
            size 0.01 0.01 0.01
          }
        }
      ]
      name "ds_left"
      boundingObject USE sensor
      physics Physics {
      }
    }
    DistanceSensor {
      translation -0.02 0 0.1
      rotation 0 1 0 -1.87
      children [
        DEF sensor Shape {
          appearance PBRAppearance {
            baseColor 0 1 1
            metalness 0
          }
          geometry Box {
            size 0.01 0.01 0.01
          }
        }
      ]
      name "ds_right"
      boundingObject USE sensor
      physics Physics {
      }
    }
    GPS {
      translation 0 0.03 0
      children [
        Solid {
          children [
            Shape {
              appearance PBRAppearance {
              }
              geometry Cylinder {
                height 0.02
                radius 0.01
              }
            }
          ]
        }
      ]
      name "global"
    }
    InertialUnit {
      translation 0 0.03 0.04
      children [
        Shape {
          appearance PBRAppearance {
            baseColor 0 0 0.7
            metalness 0
          }
          geometry Box {
            size 0.02 0.02 0.02
          }
        }
      ]
      name "imu"
    }
  ]
  name "robot2_name"
  boundingObject USE Body
  physics Physics {
  }
  controller "robot_controller_v2"
  controllerArgs [
    "2"
  ]
  supervisor TRUE
}
DEF robot3 Robot {
  translation -0.39621 0.0397206 1.29995
  rotation 7.025569999801596e-06 0.9999999999717597 -2.668669999924636e-06 0
  children [
    DistanceSensor {
      translation 0.05 0.02 -0.096
      rotation 0 -1 0 0
      children [
        DEF sensor Shape {
          appearance PBRAppearance {
            baseColor 0 1 1
            metalness 0
          }
          geometry Box {
            size 0.01 0.01 0.01
          }
        }
      ]
      name "ds_back_left"
      boundingObject USE sensor
      physics Physics {
      }
    }
    Emitter {
      channel -1
    }
    Receiver {
      channel -1
    }
    DEF Body Shape {
      appearance PBRAppearance {
        baseColor 0 1 0
        metalness 0
      }
      geometry Box {
        size 0.1 0.05 0.2
      }
    }
    HingeJoint {
      jointParameters HingeJointParameters {
        position 43883.97411442267
        anchor 0.06 0 0.05
      }
      device [
        RotationalMotor {
          name "wheel1"
        }
      ]
      endPoint Solid {
        translation 0.060000000000000026 -1.0491328273523474e-17 0.04999999999999998
        rotation 0.6663695508776137 -0.6658391141214117 0.33557397957705426 2.493580583817602
        children [
          DEF Wheel Shape {
            appearance PBRAppearance {
              baseColor 1 0 0
              metalness 0
            }
            geometry Cylinder {
              height 0.02
              radius 0.04
            }
          }
        ]
        boundingObject USE Wheel
        physics DEF Physics_wh Physics {
        }
      }
    }
    HingeJoint {
      jointParameters HingeJointParameters {
        position 40420.38141767931
        anchor -0.06 0 0.05
      }
      device [
        RotationalMotor {
          name "wheel2"
        }
      ]
      endPoint Solid {
        translation -0.06 1.590320854747017e-17 0.050000000000000024
        rotation 0.6282482371842046 -0.6277481453709124 -0.45960463276420443 4.003821890932696
        children [
          USE Wheel
        ]
        name "solid(1)"
        boundingObject USE Wheel
        physics USE Physics_wh
      }
    }
    HingeJoint {
      jointParameters HingeJointParameters {
        position 43883.97439830295
        anchor 0.06 0 -0.05
      }
      device [
        RotationalMotor {
          name "wheel3"
        }
      ]
      endPoint Solid {
        translation 0.060000000000000026 1.0487623308993143e-17 -0.04999999999999998
        rotation 0.6663960477424486 -0.6658655898944812 0.335468811885276 2.493769756750608
        children [
          USE Wheel
        ]
        name "solid(2)"
        boundingObject USE Wheel
        physics USE Physics_wh
      }
    }
    HingeJoint {
      jointParameters HingeJointParameters {
        position 40420.381760841774
        anchor -0.06 0 -0.05
      }
      device [
        RotationalMotor {
          name "wheel4"
        }
      ]
      endPoint Solid {
        translation -0.06 -1.0067787224165519e-08 -0.05000000766437837
        rotation -0.30467668251046753 0.30443415685642244 -0.9024920848813772 4.61076531870655
        children [
          USE Wheel
        ]
        name "solid(3)"
        boundingObject USE Wheel
        physics USE Physics_wh
      }
    }
    DistanceSensor {
      translation 0.02 0 0.1
      rotation 0 1 0 -1.27
      children [
        DEF sensor Shape {
          appearance PBRAppearance {
            baseColor 0 1 1
            metalness 0
          }
          geometry Box {
            size 0.01 0.01 0.01
          }
        }
      ]
      name "ds_left"
      boundingObject USE sensor
      physics Physics {
      }
    }
    DistanceSensor {
      translation -0.02 0 0.1
      rotation 0 1 0 -1.87
      children [
        DEF sensor Shape {
          appearance PBRAppearance {
            baseColor 0 1 1
            metalness 0
          }
          geometry Box {
            size 0.01 0.01 0.01
          }
        }
      ]
      name "ds_right"
      boundingObject USE sensor
      physics Physics {
      }
    }
    GPS {
      translation 0 0.03 0
      children [
        Solid {
          children [
            Shape {
              appearance PBRAppearance {
              }
              geometry Cylinder {
                height 0.02
                radius 0.01
              }
            }
          ]
        }
      ]
      name "global"
    }
    InertialUnit {
      translation 0 0.03 0.04
      children [
        Shape {
          appearance PBRAppearance {
            baseColor 0 0 0.7
            metalness 0
          }
          geometry Box {
            size 0.02 0.02 0.02
          }
        }
      ]
      name "imu"
    }
  ]
  name "robot3_name"
  boundingObject USE Body
  physics Physics {
  }
  controller "robot_controller_v2"
  controllerArgs [
    "3"
  ]
  supervisor TRUE
}
DEF mine0 Robot {
  children [
    Emitter {
    }
    Receiver {
      channel -1
    }
    Shape {
      appearance PBRAppearance {
        baseColor 1 0 0
      }
      geometry Cylinder {
        height 0.5
        radius 0.05
      }
    }
  ]
  name "mine0_name"
  controller "field_controller"
  supervisor TRUE
}
